Workbook

Sheet Epics
A1: Epics du Product Backlog
A2: Niveau stratégique — regroupement des User Stories par grand besoin métier
A5: Code | B5: Epic | C5: Module du CDC v2.4 | D5: Description | E5: Valeur métier attendue | F5: Priorité MoSCoW | G5: Ordre | H5: Statut d'affinage | I5: Nb US affinées | J5: Story points
A6: EP-01 | B6: Socle technique, comptes et sécurité d'accès | C6: Module 12 — Sécurité & Administration | D6: Fournir la fondation technique et le contrôle d'accès indispensables à toute fonctionnalité : authentification forte, gestion des comptes et des rôles, journal d'audit immuable, sauvegardes. | E6: Aucune fonctionnalité métier ne peut être livrée ni recettée sans socle d'authentification et de droits. Epic bloquant pour l'ensemble du projet. | F6: Must have | G6: 1 | H6: Affiné — Module 1 | I6: =COUNTIF('Product Backlog'!$B$6:$B$76,$A6) -> 0 | J6: =SUMIF('Product Backlog'!$B$6:$B$76,$A6,'Product Backlog'!$I$6:$I$76) -> 0
A7: EP-02 | B7: Paramétrage du programme académique A1–A4 | C7: Module 1 — Gestion académique | D7: Permettre à l'EBAC de décrire son programme officiel : Matières, Modules, Cours, coefficients, volumes horaires 15 h théorie / 15 h pratique, Matière Stage A3, Matière Soutenance A4 et évaluations de fin de cycle. | E7: Le programme est le référentiel dont dépendent les notes, les bulletins et le diplôme. Sans lui, aucun dossier étudiant n'est exploitable. | F7: Must have | G7: 2 | H7: Affiné — Module 1 | I7: =COUNTIF('Product Backlog'!$B$6:$B$76,$A7) -> 0 | J7: =SUMIF('Product Backlog'!$B$6:$B$76,$A7,'Product Backlog'!$I$6:$I$76) -> 0
A8: EP-03 | B8: Calendrier académique et référentiels | C8: Module 1 — Gestion académique | D8: Définir l'année académique, les périodes d'évaluation et de rattrapage, les salles et les promotions. | E8: Socle de données commun à tous les modules du SIG ; garantit un calendrier unique et fiable. | F8: Must have | G8: 3 | H8: Affiné — Module 1 | I8: =COUNTIF('Product Backlog'!$B$6:$B$76,$A8) -> 0 | J8: =SUMIF('Product Backlog'!$B$6:$B$76,$A8,'Product Backlog'!$I$6:$I$76) -> 0
A9: EP-04 | B9: Églises partenaires et recommandation | C9: Module 1 — Gestion académique | D9: Gérer le référentiel des Églises, leur compte partagé cloisonné et le rattachement obligatoire de chaque étudiant à son Église recommandatrice. | E9: Règle EBAC : aucun étudiant n'intègre l'école sans recommandation. Le profil Église joue un rôle essentiel dans le suivi de l'étudiant. | F9: Must have | G9: 4 | H9: Affiné — Module 1 | I9: =COUNTIF('Product Backlog'!$B$6:$B$76,$A9) -> 0 | J9: =SUMIF('Product Backlog'!$B$6:$B$76,$A9,'Product Backlog'!$I$6:$I$76) -> 0
A10: EP-05 | B10: Pré-inscription numérique et paiement en ligne | C10: Module 1 — Gestion académique | D10: Dématérialiser la constitution du dossier avant la rentrée : invitation par lien sécurisé, formulaire en ligne, dépôt de pièces, paiement Mobile Money, suivi de campagne. | E10: Décision de la Note de cadrage complémentaire n° 01 : premier gain visible de la transition numérique, attendu pour la rentrée de septembre 2026. | F10: Must have | G10: 5 | H10: Affiné — Module 1 | I10: =COUNTIF('Product Backlog'!$B$6:$B$76,$A10) -> 0 | J10: =SUMIF('Product Backlog'!$B$6:$B$76,$A10,'Product Backlog'!$I$6:$I$76) -> 0
A11: EP-06 | B11: Dossier étudiant et inscription définitive | C11: Module 1 — Gestion académique | D11: Valider l'inscription à l'arrivée, générer le matricule, ouvrir le compte portail, initialiser les matières et les cours à faire, gérer le cycle de vie du dossier. | E11: Cœur du Module 1 : le dossier étudiant alimente tous les autres modules du SIG. | F11: Must have | G11: 6 | H11: Affiné — Module 1 | I11: =COUNTIF('Product Backlog'!$B$6:$B$76,$A11) -> 0 | J11: =SUMIF('Product Backlog'!$B$6:$B$76,$A11,'Product Backlog'!$I$6:$I$76) -> 0
A12: EP-07 | B12: Promotions et avancement annuel | C12: Module 1 — Gestion académique | D12: Gérer les promotions et l'opération collective et irréversible de passage de niveau, avec conservation des cours à faire. | E12: Règle fondamentale EBAC : tous les étudiants avancent chaque année, sans redoublement ni maintien de niveau. | F12: Must have | G12: 7 | H12: Affiné — Module 1 | I12: =COUNTIF('Product Backlog'!$B$6:$B$76,$A12) -> 0 | J12: =SUMIF('Product Backlog'!$B$6:$B$76,$A12,'Product Backlog'!$I$6:$I$76) -> 0
A13: EP-08 | B13: Progression vers le diplôme et rattrapages | C13: Module 1 — Gestion académique | D13: Suivre le taux de matières validées, planifier les rattrapages inter-annuels, délivrer diplômes et attestations de formation partielle. | E13: Le diplôme se construit par accumulation de validations : c'est le principe directeur du système EBAC. | F13: Must have | G13: 8 | H13: Affiné — Module 1 | I13: =COUNTIF('Product Backlog'!$B$6:$B$76,$A13) -> 0 | J13: =SUMIF('Product Backlog'!$B$6:$B$76,$A13,'Product Backlog'!$I$6:$I$76) -> 0
A14: EP-09 | B14: Portails et tableaux de bord du Module 1 | C14: Modules 8, 9 et 11 — Portails & Reporting | D14: Ouvrir aux étudiants, aux Églises, à la Direction, au Gestionnaire et au Secrétariat les vues de consultation et de pilotage alimentées par le Module 1. | E14: Rend la valeur du Module 1 visible pour le client et les utilisateurs finaux ; condition de l'adhésion au projet. | F14: Must have | G14: 9 | H14: Affiné — Module 1 | I14: =COUNTIF('Product Backlog'!$B$6:$B$76,$A14) -> 0 | J14: =SUMIF('Product Backlog'!$B$6:$B$76,$A14,'Product Backlog'!$I$6:$I$76) -> 0
A15: EP-10 | B15: Notes, évaluations et bulletins | C15: Module 2 — Notes & Bulletins | D15: Saisie conditionnée par la présence, calcul de la note de matière sur les seuls cours suivis, workflow de validation, génération et publication des bulletins, corrections tracées. | E15: Module critique : les notes engagent la responsabilité académique de l'EBAC. | F15: Must have | G15: 10 | H15: À affiner — Phase 2 | I15: =COUNTIF('Product Backlog'!$B$6:$B$76,$A15) -> 0 | J15: =SUMIF('Product Backlog'!$B$6:$B$76,$A15,'Product Backlog'!$I$6:$I$76) -> 0
A16: EP-11 | B16: Suivi pédagogique et journal de cours | C16: Module 3 — Suivi pédagogique | D16: Planification des enseignements, journal de cours numérique, liste de présence, taux de réalisation, alertes pédagogiques, bibliothèque de supports. | E16: Élément différenciateur du système : source officielle des données de présence qui conditionnent les notes. | F16: Must have | G16: 11 | H16: À affiner — Phase 2 | I16: =COUNTIF('Product Backlog'!$B$6:$B$76,$A16) -> 0 | J16: =SUMIF('Product Backlog'!$B$6:$B$76,$A16,'Product Backlog'!$I$6:$I$76) -> 0
A17: EP-12 | B17: Gestion des stages — Matière Stage A3 | C17: Module 4 — Stages | D17: Affectation en Église, journal hebdomadaire, validation par le représentant d'Église, grille d'évaluation, validation Direction. | E17: La Matière Stage est obligatoire pour le diplôme ; elle mobilise pleinement le profil Église. | F17: Should have | G17: 12 | H17: À affiner — Phase 2 | I17: =COUNTIF('Product Backlog'!$B$6:$B$76,$A17) -> 0 | J17: =SUMIF('Product Backlog'!$B$6:$B$76,$A17,'Product Backlog'!$I$6:$I$76) -> 0
... A26: EP-21 | B26: Déploiement et mise en production | C26: Transverse | D26: Environnements, scripts de déploiement et de restauration, bascule en production, plan de reprise des données existantes. | E26: Conditionne la mise à disposition réelle du système aux utilisateurs de l'EBAC. | F26: Must have | G26: 21 | H26: Transverse | I26: =COUNTIF('Product Backlog'!$B$6:$B$76,$A26) -> 0 | J26: =SUMIF('Product Backlog'!$B$6:$B$76,$A26,'Product Backlog'!$I$6:$I$76) -> 0
B27: TOTAL | I27: =SUM(I6:I26) -> 0 | J27: =SUM(J6:J26) -> 0

Sheet Product Backlog
A1: Product Backlog — Module 1 : Gestion académique
A2: Liste ordonnée et vivante. Propriété du Product Owner. Les tâches techniques n'y figurent pas : elles sont créées au Sprint Planning (Manuel SOUMAFÊ §07).
A5: ID | B5: Epic | C5: Module du CDC | D5: Profil / Acteur | E5: Catégorie | F5: User Story (En tant que… Je veux… Afin de…) | G5: Critères d'acceptation (format Gherkin) | H5: Priorité MoSCoW | I5: Story points | J5: Sprint cible | K5: Release | L5: Affectation | M5: DoR | N5: Statut
A6: US-001 | B6: EP-01 | C6: Module 12 — Sécurité & Administration | D6: Administrateur | E6: Authentification | F6: En tant qu'Administrateur, je veux me connecter avec un mot de passe et un code de vérification (2FA), afin de sécuriser l'accès à un compte à privilèges élevés. | G6: GIVEN un administrateur enregistré WHEN il saisit des identifiants valides THEN un code OTP à 6 chiffres lui est envoyé et l'accès n'est ouvert qu'après saisie correcte du code. GIVEN un compte administrateur WHEN 5 tentatives échouent consécutivement THEN le compte est bloqué automatiquement et l'événement est journalisé. GIVEN un code OTP émis WHEN plus de 10 minutes se sont écoulées THEN le code est refusé et un nouveau code doit être demandé. | H6: Must have | I6: 5 | J6: Sprint 1 | K6: R1 | L6: Back + Front | M6: Oui | N6: À faire
A7: US-002 | B7: EP-01 | C7: Module 12 — Sécurité & Administration | D7: Administrateur | E7: Comptes & droits | F7: En tant qu'Administrateur, je veux créer un compte utilisateur en lui attribuant un rôle, afin de donner à chaque personne l'accès strictement adapté à sa fonction. | G7: GIVEN le formulaire de création de compte WHEN l'administrateur saisit un e-mail déjà utilisé THEN la création est refusée avec un message explicite. GIVEN un compte créé WHEN l'enregistrement est validé THEN un mot de passe temporaire est généré, transmis par e-mail, et son changement est imposé à la première connexion. GIVEN la liste des rôles WHEN l'administrateur choisit un rôle THEN seuls les 7 profils officiels EBAC sont proposés. | H7: Must have | I7: 5 | J7: Sprint 1 | K7: R1 | L7: Back + Front | M7: Oui | N7: À faire
A8: US-003 | B8: EP-01 | C8: Module 12 — Sécurité & Administration | D8: Administrateur | E8: Comptes & droits | F8: En tant qu'Administrateur, je veux suspendre, bloquer, réactiver ou désactiver un compte, afin de réagir immédiatement à un incident de sécurité ou à un départ. | G8: GIVEN un compte actif WHEN l'administrateur le bloque THEN les sessions ouvertes de cet utilisateur sont invalidées dans la minute. GIVEN un compte suspendu WHEN l'utilisateur tente de se connecter THEN l'accès est refusé avec un message l'invitant à contacter l'administration. GIVEN tout changement de statut WHEN il est enregistré THEN l'auteur, la date et le motif sont horodatés dans l'historique du compte. | H8: Must have | I8: 3 | J8: Sprint 1 | K8: R1 | L8: Back + Front | M8: Oui | N8: À faire
A9: US-004 | B9: EP-01 | C9: Module 12 — Sécurité & Administration | D9: Administrateur | E9: Comptes & droits | F9: En tant qu'Administrateur, je veux activer ou désactiver individuellement chaque permission d'un rôle, afin d'ajuster finement les droits selon le principe du moindre privilège. | G9: GIVEN la matrice rôle × permission WHEN l'administrateur modifie une case THEN l'effet est immédiat pour tous les utilisateurs porteurs de ce rôle. GIVEN un utilisateur connecté WHEN une de ses permissions est retirée THEN l'écran concerné devient inaccessible sans nécessiter de déconnexion complète. GIVEN toute modification de la matrice WHEN elle est enregistrée THEN elle est tracée dans le journal d'audit. | H9: Should have | I9: 8 | J9: Sprint 11 | K9: R5 | L9: Back + Front | M9: Oui | N9: À faire
A10: US-005 | B10: EP-01 | C10: Module 12 — Sécurité & Administration | D10: Administrateur | E10: Journal d'audit | F10: En tant qu'Administrateur, je veux consulter un journal d'audit listant toutes les actions sensibles, afin de garantir la traçabilité complète du système. | G10: GIVEN le journal d'audit WHEN un administrateur tente de modifier ou de supprimer une entrée THEN l'action est impossible (journal immuable). GIVEN le journal WHEN l'administrateur filtre par utilisateur, type d'action ou plage de dates THEN seules les entrées correspondantes sont affichées. GIVEN une action sensible (connexion, changement de droits, validation de notes, opération financière) WHEN elle est exécutée THEN une entrée est créée avec auteur, date, adresse IP et objet concerné. | H10: Must have | I10: 5 | J10: Sprint 10 | K10: R4 | L10: Back + Front | M10: Oui | N10: À faire
A11: US-006 | B11: EP-01 | C11: Module 12 — Sécurité & Administration | D11: Administrateur | E11: Journal d'audit | F11: En tant qu'Administrateur, je veux exporter le journal d'audit au format CSV, afin de le transmettre dans le cadre d'un contrôle externe. | G11: GIVEN un filtre appliqué WHEN l'administrateur lance l'export THEN le fichier généré contient exactement les lignes affichées. GIVEN un export réalisé WHEN le fichier est produit THEN son nom porte un horodatage et l'export lui-même est journalisé. | H11: Should have | I11: 3 | J11: Sprint 11 | K11: R5 | L11: Back | M11: Oui | N11: À faire
A12: US-007 | B12: EP-01 | C12: Module 12 — Sécurité & Administration | D12: Tous profils | E12: Authentification | F12: En tant qu'utilisateur du système, je veux réinitialiser mon mot de passe de façon autonome, afin de retrouver l'accès sans solliciter l'administration. | G12: GIVEN un e-mail enregistré WHEN l'utilisateur demande une réinitialisation THEN un lien à usage unique valable 30 minutes lui est envoyé. GIVEN un lien de réinitialisation WHEN il a déjà été utilisé ou est expiré THEN il est refusé. GIVEN un nouveau mot de passe WHEN il ne respecte pas la politique de complexité THEN il est rejeté avec l'indication des règles non satisfaites. | H12: Must have | I12: 3 | J12: Sprint 1 | K12: R1 | L12: Back + Front | M12: Oui | N12: À faire
A13: US-008 | B13: EP-01 | C13: Module 12 — Sécurité & Administration | D13: Administrateur | E13: Sécurité | F13: En tant qu'Administrateur, je veux paramétrer la politique de mots de passe et la durée des sessions, afin d'adapter le niveau de sécurité aux exigences de l'EBAC. | G13: GIVEN les paramètres de sécurité WHEN l'administrateur modifie la longueur minimale ou la durée d'inactivité THEN la nouvelle règle s'applique dès la connexion suivante. GIVEN une session inactive WHEN la durée paramétrée est dépassée THEN l'utilisateur est déconnecté automatiquement. | H13: Should have | I13: 3 | J13: Sprint 11 | K13: R5 | L13: Back | M13: Oui | N13: À faire
A14: US-009 | B14: EP-01 | C14: Module 12 — Sécurité & Administration | D14: Administrateur | E14: Comptes & droits | F14: En tant qu'Administrateur, je veux consulter l'historique des actions réalisées sur un compte, afin de comprendre son évolution en cas de litige. | G14: GIVEN un compte utilisateur WHEN l'administrateur ouvre son historique THEN les événements sont affichés par ordre chronologique décroissant et en lecture seule. GIVEN cet historique WHEN il est affiché THEN il précise pour chaque événement l'auteur, la date et la nature du changement. | H14: Should have | I14: 3 | J14: Sprint 11 | K14: R5 | L14: Back + Front | M14: Oui | N14: À faire
A15: US-010 | B15: EP-01 | C15: Module 12 — Sécurité & Administration | D15: Administrateur | E15: Paramètres système | F15: En tant qu'Administrateur, je veux modifier les paramètres globaux du système, afin d'adapter son comportement sans intervention du prestataire. | G15: GIVEN un paramètre global WHEN il est modifié THEN la valeur précédente, l'auteur et la date sont conservés. GIVEN un paramètre critique WHEN il est modifié THEN une confirmation explicite est demandée. | H15: Could have | I15: 3 | J15: Sprint 12 | K15: R5 | L15: Back + Front | M15: Oui | N15: À faire
A16: US-011 | B16: EP-01 | C16: Module 12 — Sécurité & Administration | D16: Administrateur | E16: Sauvegardes | F16: En tant qu'Administrateur, je veux consulter l'état des sauvegardes automatiques, afin de m'assurer que les données de l'école sont protégées. | G16: GIVEN la page Sauvegardes WHEN elle est ouverte THEN la liste affiche pour chaque sauvegarde la date, la taille et le statut (Réussie / Échouée). GIVEN une sauvegarde en échec WHEN elle est détectée THEN une alerte est remontée à l'administrateur. | H16: Should have | I16: 3 | J16: Sprint 12 | K16: R5 | L16: Back + Front | M16: Oui | N16: À faire
A17: US-012 | B17: EP-01 | C17: Module 12 — Sécurité & Administration | D17: Administrateur | E17: Sauvegardes | F17: En tant qu'Administrateur, je veux déclencher une sauvegarde manuelle, afin de sécuriser les données avant une opération sensible. | G17: GIVEN la page Sauvegardes WHEN l'administrateur déclenche une sauvegarde THEN son avancement est affiché en temps réel. GIVEN une sauvegarde manuelle terminée WHEN elle réussit THEN elle apparaît dans la liste avec la mention « Manuelle » et le nom de l'auteur. | H17: Could have | I17: 3 | J17: Sprint 12 | K17: R5 | L17: Back | M17: Oui | N17: À faire
... A90: US-085 | B90: EP-04 | C90: Module 1 — Gestion académique | D90: Secrétariat | E90: Églises | F90: En tant que Secrétariat, je veux consulter la liste des étudiants recommandés par Église en la croisant avec leur niveau académique, afin de savoir précisément combien d'étudiants de chaque Église se trouvent à chaque niveau. | G90: GIVEN la fiche d'une Église WHEN j'ouvre la répartition par niveau THEN le nombre d'étudiants recommandés par cette Église est affiché pour chacun des niveaux A1 à A4. GIVEN cette répartition WHEN un niveau est sélectionné THEN la liste nominative des étudiants de cette Église à ce niveau s'affiche. | H90: Could have | I90: 2 | J90: Sprint 3 | K90: R2 | L90: Back + Front | M90: Oui | N90: À faire
F91: TOTAL DU BACKLOG AFFINÉ | H91: =COUNTA(A6:A90)&" User Stories" -> 0 | I91: =SUM(I6:I90) -> 0
A93: Légende — Colonnes à mettre à jour par l'équipe : « DoR » (M) et « Statut » (N), via les listes déroulantes. Les colonnes A à L relèvent du Product Owner. La colonne « Story points » applique la suite de Fibonacci du Manuel SOUMAFÊ (1, 2, 3, 5, 8, 13, 21).

Sheet Objectif Sprints
A1: Plan de sprints
A2: Sprints de 2 semaines (10 jours ouvrés) — Manuel Agile / SCRUM SF SOUMAFÊ §06
A5: Sprint | B5: Début | C5: Fin | D5: Release | E5: Capacité (pts) | F5: Points planifiés | G5: Nb US | H5: Sprint Goal | I5: Statut
A6: Sprint 0 | B6: 06/08/2026 | C6: 07/08/2026 | D6: — | E6: 0 | F6: =SUMIF('Product Backlog'!$J$6:$J$90,$A6,'Product Backlog'!$I$6:$I$90) -> 0 | G6: =COUNTIF('Product Backlog'!$J$6:$J$90,$A6) -> 0 | H6: Setup Agile : outillage, dépôt Git, conventions d'équipe, environnements, constitution et estimation du backlog initial. | I6: Planifié
A7: Sprint 1 | B7: 10/08/2026 | C7: 21/08/2026 | D7: R1 | E7: 20 | F7: =SUMIF('Product Backlog'!$J$6:$J$90,$A7,'Product Backlog'!$I$6:$I$90) -> 0 | G7: =COUNTIF('Product Backlog'!$J$6:$J$90,$A7) -> 0 | H7: Ce sprint, nous livrerons l'authentification sécurisée et la gestion des comptes pour l'Administrateur de l'EBAC, afin que la plateforme puisse être ouverte aux premiers utilisateurs. | I7: Planifié
A8: Sprint 2 | B8: 24/08/2026 | C8: 04/09/2026 | D8: R1 | E8: 22 | F8: =SUMIF('Product Backlog'!$J$6:$J$90,$A8,'Product Backlog'!$I$6:$I$90) -> 0 | G8: =COUNTIF('Product Backlog'!$J$6:$J$90,$A8) -> 0 | H8: Ce sprint, nous livrerons la pré-inscription numérique pour les candidats invités, afin qu'ils constituent leur dossier à distance avant la rentrée. | I8: Planifié
A9: Sprint 3 | B9: 07/09/2026 | C9: 18/09/2026 | D9: R2 | E9: 50 | F9: =SUMIF('Product Backlog'!$J$6:$J$90,$A9,'Product Backlog'!$I$6:$I$90) -> 0 | G9: =COUNTIF('Product Backlog'!$J$6:$J$90,$A9) -> 0 | H9: Ce sprint, nous livrerons au Secrétariat académique et à la Direction les vues de consultation des dossiers étudiants (par niveau, promotion, année d'entrée, Église recommandatrice, statut de pré-inscription et complétude des pièces) ainsi que le contrôle et la validation de la recommandation d'un étudiant par son Église, afin que le Secrétariat puisse fiabiliser les inscriptions et ouvrir les accès portail en toute autonomie. | I9: Planifié
A10: Sprint 4 | B10: 21/09/2026 | C10: 02/10/2026 | D10: À confirmer | E10: À confirmer | F10: 42 | G10: 11 | H10: Permettre aux enseignants de consulter leurs cours et plannings, de relever et valider les présences, et aux étudiants de consulter leurs matières, cours à faire, progression et planning dans un espace cloisonné. | I10: Proposé — capacité à valider

Sheet Sprint Backlog du sprint 0
A1: Sprint Backlog — Sprint 0
A2: 10/08/2026 · Sprint de démarrage (setup Agile), créé en Sprint Planning
A4: Sprint Goal | B4: Setup Agile : outillage, dépôt Git, conventions d'équipe, environnements, constitution et estimation du backlog initial.
A6: ID tâche | B6: User Story | C6: Tâche technique | D6: Assigné à | E6: Date début | F6: Échéance | G6: Estimation (h) | H6: Reste à faire (h) | I6: Point | J6: Statut | K6: Observation
A7: T-001 | B7: Transverse | C7: Sélection et configuration de l'outillage frontend (dépendances, structure des écrans) | D7: M. KOUASSI | E7: 46244 | F7: 46244 | G7: 2 | H7: =0 -> 0 | J7: À faire
A8: T-002 | B8: Transverse | C8: Mise en place du client API | D8: M. KOUASSI | E8: 46244 | F8: 46244 | G8: 3 | H8: =0 -> 0 | J8: À faire
A9: T-003 | B9: Transverse | C9: Définition des conventions d'écrans et du design system | D9: M. KOUASSI | E9: 46244 | F9: 46244 | G9: 4 | H9: =0 -> 0 | J9: À faire
C10: TOTAL | G10: =SUM(G7:G9) -> 0 | H10: =SUM(H7:H9) -> 0

Sheet Sprint Backlog  API du sprint 0
A1: Sprint Backlog — Sprint 0 API
A2: 10/08/2026 · Sprint de démarrage (setup Agile), créé en Sprint Planning
A4: Sprint Goal | B4: Setup Agile : outillage, dépôt Git, conventions d'équipe, environnements, constitution et estimation du backlog initial.
A6: ID tâche | B6: User Story | C6: Tâche technique | D6: Assigné à | E6: Date début | F6: Échéance | G6: Estimation (h) | H6: Reste à faire (h) | I6: Point | J6: Statut | K6: Observation
A7: T-001 | B7: Transverse | C7: Sélection et configuration de l'outillage backend (framework API, dépendances, structure du projet) | D7: ZRAN | E7: 46244 | F7: 46244 | G7: 2 | H7: =0 -> 0 | J7: À faire
A8: T-002 | B8: Transverse | C8: Mise en place du dépôt Git backend et de la structure des applications/modules | D8: ZRAN | E8: 46244 | F8: 46244 | G8: 3 | H8: =0 -> 0 | J8: À faire
A9: T-003 | B9: Transverse | C9: Configuration de la base de données et des environnements (PostgreSQL, variables d'environnement) | D9: ZRAN | E9: 46244 | F9: 46244 | G9: 4 | H9: =0 -> 0 | J9: À faire
A10: T-004 | B10: Transverse | C10: Définition des conventions API (nommage des endpoints, format des réponses JSON, gestion des erreurs) | D10: ZRAN | E10: 46244 | F10: 46244 | G10: 5 | H10: =0 -> 0 | J10: À faire
C11: TOTAL | G11: =SUM(G7:G10) -> 0 | H11: =SUM(H7:H10) -> 0

Sheet Sprint Backlog du sprint 1
A1: Sprint Backlog — Sprint 1
A2: Du 10/08/2026 au 21/08/2026 · Décomposition en tâches techniques (8 h maximum par tâche), créée en Sprint Planning
A4: Sprint Goal | B4: Ce sprint, nous livrerons l'authentification sécurisée et la gestion des comptes pour l'Administrateur de l'EBAC, afin que la plateforme puisse être ouverte aux premiers utilisateurs.
A6: ID tâche | B6: User Story | C6: Tâche technique | D6: Assigné à | E6: Date début | F6: Échéance | G6: Estimation (h) | H6: Reste à faire (h) | I6: Point | J6: Statut | K6: Observation
A7: T-101 | B7: US-001 | C7: Écran de connexion responsive conforme à la maquette V1 | D7: M. KOUASSI | E7: 46245 | F7: 46245 | G7: 1 | H7: 0 | I7: 3 | J7: À faire
A8: T-102 | B8: US-001 | C8: Intégration API de connexion (login) et gestion des erreurs d'authentification | D8: M. KOUASSI | E8: 46245 | F8: 46245 | G8: 2 | H8: =G8 -> 0 | I8: 4 | J8: À faire
A9: T-103 | B9: US-001 | C9: Écran de saisie du code OTP et gestion des messages d'erreur | D9: M. KOUASSI | E9: 46245 | F9: 46245 | G9: 1 | H9: =G9 -> 0 | I9: 2 | J9: À faire
A10: T-104 | B10: US-001 | C10: Intégration API de vérification du code OTP et gestion de l'expiration | D10: M. KOUASSI | E10: 46245 | F10: 46245 | G10: 2 | H10: =G10 -> 0 | I10: 3 | J10: À faire
A11: T-105 | B11: US-002 | C11: Écrans liste des comptes et formulaire de création | D11: M. KOUASSI | E11: 46245 | F11: 46245 | G11: 2 | H11: =G11 -> 0 | I11: 2 | J11: À faire
A12: T-106 | B12: US-002 | C12: Intégration API CRUD des comptes (création, liste, contrôle d'unicité de l'e-mail) | D12: M. KOUASSI | E12: 46245 | F12: 46245 | G12: 3 | H12: =G12 -> 0 | I12: 3 | J12: À faire
A13: T-107 | B13: US-002 | C13: Écran de changement de mot de passe imposé à la première connexion | D13: M. KOUASSI | E13: 46245 | F13: 46245 | G13: 1 | H13: =G13 -> 0 | I13: 2 | J13: À faire
A14: T-108 | B14: US-002 | C14: Intégration API de changement de mot de passe | D14: M. KOUASSI | E14: 46245 | F14: 46245 | G14: 2 | H14: =G14 -> 0 | I14: 4 | J14: À faire
A15: T-111 | B15: US-007 | C15: Écrans « Mot de passe oublié » et « Nouveau mot de passe » | D15: M. KOUASSI | E15: 46246 | F15: 46246 | G15: 1 | H15: =G15 -> 0 | I15: 1 | J15: À faire
A16: T-112 | B16: US-007 | C16: Intégration API de réinitialisation du mot de passe (jeton, politique de complexité) | D16: M. KOUASSI | E16: 46246 | F16: 46246 | G16: 2 | H16: =G16 -> 0 | I16: 3 | J16: À faire
A17: T-113 | B17: US-024 | C17: Écran de paramétrage de l'année académique | D17: M. KOUASSI | E17: 46246 | F17: 46246 | G17: 2 | H17: =G17 -> 0 | I17: 3 | J17: À faire
A18: T-114 | B18: US-024 | C18: Intégration API de l'année académique (CRUD, contrôle de chevauchement) | D18: M. KOUASSI | E18: 46246 | F18: 46246 | G18: 2 | H18: =G18 -> 0 | I18: 4 | J18: À faire
A19: T-115 | B19: US-027 | C19: Écran de gestion des promotions et compteurs d'effectifs | D19: M. KOUASSI | E19: 46246 | F19: 46246 | G19: 1 | H19: =G19 -> 0 | I19: 2 | J19: À faire
A20: T-116 | B20: US-027 | C20: Intégration API des promotions (format PROMO-AAAA, calcul des effectifs) | D20: M. KOUASSI | E20: 46246 | F20: 46246 | G20: 2 | H20: =G20 -> 0 | I20: 3 | J20: À faire
C21: TOTAL | G21: =SUM(G7:G20) -> 0 | H21: =SUM(H7:H20) -> 0

Sheet Sprint Backlog API du sprint 1
A1: Sprint Backlog — Sprint 1 API
A2: Du 10/08/2026 au 21/08/2026 · Décomposition en tâches techniques (8 h maximum par tâche), créée en Sprint Planning
A4: Sprint Goal | B4: Ce sprint, nous livrerons l'authentification sécurisée et la gestion des comptes pour l'Administrateur de l'EBAC, afin que la plateforme puisse être ouverte aux premiers utilisateurs.
A6: ID tâche | B6: User Story | C6: Tâche technique | D6: Assigné à | E6: Date début | F6: Échéance | G6: Estimation (h) | H6: Reste à faire (h) | I6: Point | J6: Statut | K6: Observation
A7: T-102 | B7: US-001 | C7: Développer l'API de connexion avec génération et envoi du code OTP (2FA) | D7: ZRAN | E7: 46245 | F7: 46245 | G7: 2 | H7: =G7 -> 0 | I7: 4 | J7: À faire
A8: T-103 | B8: US-001 | C8: Développer l'API de vérification du code OTP et la gestion de son expiration (10 min) | D8: ZRAN | E8: 46245 | F8: 46245 | G8: 1 | H8: =G8 -> 0 | I8: 2 | J8: À faire
A9: T-104 | B9: US-001 | C9: Implémenter le blocage automatique après 5 échecs de connexion consécutifs | D9: ZRAN | E9: 46245 | F9: 46245 | G9: 2 | H9: =G9 -> 0 | I9: 3 | J9: À faire
A10: T-105 | B10: US-002 | C10: Développer les endpoints CRUD des comptes utilisateurs et le contrôle d'unicité de l'e-mail | D10: ZRAN | E10: 46245 | F10: 46245 | G10: 2 | H10: =G10 -> 0 | I10: 2 | J10: À faire
A11: T-106 | B11: US-002 | C11: Implémenter le mot de passe temporaire et le changement forcé à la première connexion | D11: ZRAN | E11: 46245 | F11: 46245 | G11: 3 | H11: =G11 -> 0 | I11: 3 | J11: À faire
A12: T-107 | B12: US-002 | C12: Développer les endpoints de suspension, blocage, réactivation et désactivation de compte | D12: ZRAN | E12: 46245 | F12: 46245 | G12: 1 | H12: =G12 -> 0 | I12: 2 | J12: À faire
A13: T-108 | B13: US-002 | C13: Implémenter l'invalidation immédiate des sessions actives lors d'un changement de statut | D13: ZRAN | E13: 46245 | F13: 46245 | G13: 2 | H13: =G13 -> 0 | I13: 4 | J13: À faire
A14: T-111 | B14: US-007 | C14: Développer la matrice rôle × permission avec application immédiate des changements | D14: ZRAN | E14: 46246 | F14: 46246 | G14: 1 | H14: =G14 -> 0 | I14: 1 | J14: À faire
A15: T-112 | B15: US-007 | C15: Développer l'API de réinitialisation autonome du mot de passe (lien à usage unique, 30 min) | D15: ZRAN | E15: 46246 | F15: 46246 | G15: 2 | H15: =G15 -> 0 | I15: 3 | J15: À faire
A16: T-114 | B16: US-024 | C16: Développer l'API de paramétrage de la politique de sécurité (mots de passe, durée de session) | D16: ZRAN | E16: 46246 | F16: 46246 | G16: 2 | H16: =G16 -> 0 | I16: 4 | J16: À faire
A17: T-116 | B17: US-027 | C17: Écrire les tests automatisés et documenter les endpoints de sécurité | D17: ZRAN | E17: 46246 | F17: 46246 | G17: 2 | H17: =G17 -> 0 | I17: 3 | J17: À faire
C18: TOTAL | G18: =SUM(G7:G17) -> 0 | H18: =SUM(H7:H17) -> 0

Sheet Sprint Backlog du sprint 2
A1: Sprint Backlog — Sprint 2
A2: Du 24/08/2026 au 04/09/2026 · Décomposition en tâches techniques (8 h maximum par tâche), créée en Sprint Planning
A4: Sprint Goal | B4: Ce sprint, nous livrerons la pré-inscription numérique pour les candidats invités, afin qu'ils constituent leur dossier à distance avant la rentrée.
A6: ID tâche | B6: User Story | C6: Tâche technique | D6: Assigné à | E6: Date début | F6: Échéance | G6: Estimation (h) | H6: Reste à faire (h) | I6: Point | J6: Statut | K6: Observation
A7: T-201 | B7: US-029 | C7: Écran de gestion des Églises (liste et formulaire) | D7: M. KOUASSI | G7: 0 | H7: =G7 -> 0 | J7: À faire
A8: T-202 | B8: US-029 | C8: Intégration API CRUD Églises (création, modification, désactivation) | D8: M. KOUASSI | G8: 0 | H8: =G8 -> 0 | J8: À faire
A9: T-203 | B9: US-032 | C9: Ajout du champ Église recommandatrice obligatoire dans le formulaire de dossier étudiant | D9: M. KOUASSI | G9: 0 | H9: =G9 -> 0 | J9: À faire
A10: T-204 | B10: US-032 | C10: Intégration API du contrôle de rattachement et affichage des erreurs | D10: M. KOUASSI | G10: 0 | H10: =G10 -> 0 | J10: À faire
A11: T-209 | B11: US-036 | C11: Écran du formulaire de pré-inscription (multi-étapes) | D11: M. KOUASSI | G11: 0 | H11: =G11 -> 0 | J11: À faire
A12: T-210 | B12: US-036 | C12: Intégration API de soumission du formulaire et gestion des erreurs de validation | D12: M. KOUASSI | G12: 0 | H12: =G12 -> 0 | J12: À faire
A13: T-212 | B13: US-036 | C13: Écran de l'accusé de réception (statut « Pré-inscrit ») | D13: M. KOUASSI | G13: 0 | H13: =G13 -> 0 | J13: À faire
C14: TOTAL | G14: =SUM(G7:G13) -> 0 | H14: =SUM(H7:H13) -> 0

Sheet Sprint Backlog API du sprint 2
A1: Sprint Backlog — Sprint 2 API
A2: Du 24/08/2026 au 04/09/2026 · Décomposition en tâches techniques (8 h maximum par tâche), créée en Sprint Planning
A4: Sprint Goal | B4: Ce sprint, nous livrerons la pré-inscription numérique pour les candidats invités, afin qu'ils constituent leur dossier à distance avant la rentrée.
A6: ID tâche | B6: User Story | C6: Tâche technique | D6: Assigné à | E6: Date début | F6: Échéance | G6: Estimation (h) | H6: Reste à faire (h) | I6: Statut | J6: Observation
A7: API-02-03 | B7: US-032 | C7: Développer les endpoints CRUD des matières | D7: ZRAN | E7: 1/608/2026 | F7: 46250 | G7: 1 | H7: =G7 -> 0 | I7: À faire
A8: API-02-04 | B8: US-032 | C8: Développer les endpoints CRUD des modules et des cours | D8: ZRAN | E8: 46250 | F8: 46250 | G8: 1 | H8: =G8 -> 0 | I8: À faire
A9: API-02-09 | B9: US-029 | C9: Ajouter les filtres par niveau, module, matière et année académique | D9: ZRAN | E9: 46250 | F9: 46250 | G9: 1 | H9: =G9 -> 0 | I9: À faire
A10: API-03-02 | B10: US-036 | C10: Développer l'API CRUD des années académiques | D10: ZRAN | E10: 46250 | F10: 46250 | G10: 1 | H10: =G10 -> 0 | I10: À faire
A11: API-03-03 | B11: US-036 | C11: Garantir qu'une seule année académique soit active | D11: ZRAN | E11: 46250 | F11: 46250 | G11: 1 | H11: =G11 -> 0 | I11: À faire
A12: API-03-07 | B12: US-032 | C12: Développer les endpoints CRUD des salles et promotions | D12: ZRAN | E12: 46250 | F12: 46250 | G12: 1 | H12: =G12 -> 0 | I12: À faire
A13: API-03-08 | B13: US-036 | C13: Développer l'API du calendrier académique consolidé | D13: ZRAN | E13: 46250 | F13: 46250 | G13: 1 | H13: =G13 -> 0 | I13: À faire
A14: API-03-09 | B14: US-036 | C14: Ajouter les filtres par année, période, salle et promotion | D14: ZRAN | E14: 46250 | F14: 46250 | G14: 1 | H14: =G14 -> 0 | I14: À faire
A15: API-03-10 | B15: US-036 | C15: Écrire les tests et documenter les endpoints | D15: ZRAN | E15: 46250 | F15: 46250 | G15: 1 | H15: =G15 -> 0 | I15: À faire
A16: API-04-02 | B16: US-029 | C16: Développer les endpoints CRUD des Églises | D16: ZRAN | E16: 46251 | F16: 46251 | G16: 1 | H16: =G16 -> 0 | I16: À faire
A17: API-04-04 | B17: US-032 | C17: Créer et gérer les comptes utilisateurs rattachés aux Églises | D17: ZRAN | E17: 46251 | F17: 46251 | G17: 1 | H17: =G17 -> 0 | I17: À faire
A18: API-04-05 | B18: US-036 | C18: Implémenter le cloisonnement des données par Église | D18: ZRAN | E18: 46251 | F18: 46251 | G18: 1 | H18: =G18 -> 0 | I18: À faire
A19: API-04-06 | B19: US-036 | C19: Ajouter l'Église recommandatrice au dossier étudiant | D19: ZRAN | E19: 46251 | F19: 46251 | G19: 1 | H19: =G19 -> 0 | I19: À faire
... A33: API-08-03 | B33: US-036 | C33: Développer l'API de consultation de la progression d'un étudiant | D33: ZRAN | E33: 46255 | F33: 46255 | G33: 1 | H33: =G33 -> 0 | I33: À faire

Sheet Sprint Backlog du sprint 3
A1: Sprint Backlog — Sprint 3 Front-end
A3: Sprint Goal | B3: Ce sprint, nous livrerons au Secrétariat académique et à la Direction les vues de consultation des dossiers étudiants (par niveau, promotion, année d'entrée, Église recommandatrice, statut de pré-inscription et complétude des pièces) ainsi que le contrôle et la validation de la recommandation d'un étudiant par son Église, afin que le Secrétariat puisse fiabiliser les inscriptions et ouvrir les accès portail en toute autonomie.
A5: ID tâche | B5: User Story | C5: Profil / Acteur | D5: Catégorie | E5: Tâche technique | F5: Assigné à | G5: Date début | H5: Échéance | I5: Estimation (h) | J5: Reste à faire (h) | K5: Point | L5: Statut | M5: Observation
A6: T-301 | B6: US-043 | C6: Secrétariat | D6: Dossier étudiant | E6: Écran de validation de l'inscription définitive (vérification du dossier et bouton de validation) | F6: M. KOUASSI | G6: 46261 | H6: 46261 | I6: 3 | J6: =I6 -> 0 | K6: 3 | L6: Terminée
A7: T-301-I | B7: US-043 | C7: Secrétariat | D7: Dossier étudiant | E7: Intégration API de validation de l'inscription définitive et contrôle du dossier | F7: M. KOUASSI | G7: 46261 | H7: 46261 | I7: 2 | J7: =I7 -> 0 | K7: 2 | L7: À faire | M7: En attente de l'api
A8: T-302 | B8: US-044 | C8: Système | D8: Dossier étudiant | E8: Affichage du matricule généré automatiquement sur la fiche étudiant après validation | F8: M. KOUASSI | G8: 46261 | H8: 46261 | I8: 1 | J8: =I8 -> 0 | K8: 1 | L8: Terminée
A9: T-302-I | B9: US-044 | C9: Système | D9: Dossier étudiant | E9: Intégration API de génération et récupération du matricule étudiant | F9: M. KOUASSI | G9: 46261 | H9: 46261 | I9: 2 | J9: =I9 -> 0 | K9: 2 | L9: À faire | M9: En attente de l'api
A10: T-303 | B10: US-049 | C10: Secrétariat | D10: Dossier étudiant | E10: Écran liste des étudiants avec filtre par niveau (A1 à A4) et compteur d'effectif | F10: M. KOUASSI | G10: 46261 | H10: 46261 | I10: 2 | J10: =I10 -> 0 | K10: 2 | L10: Terminée
A11: T-303-I | B11: US-049 | C11: Secrétariat | D11: Dossier étudiant | E11: Intégration API de la liste des étudiants avec filtres par niveau (A1–A4) et compteur d'effectif | F11: M. KOUASSI | G11: 46261 | H11: 46261 | I11: 3 | J11: =I11 -> 0 | K11: 3 | L11: À faire | M11: En attente de l'api
A12: T-304 | B12: US-051 | C12: Secrétariat | D12: Exports | E12: Écran liste des étudiants par promotion avec regroupement par année d'entrée | F12: M. KOUASSI | G12: 46261 | H12: 46261 | I12: 2 | J12: =I12 -> 0 | K12: 2 | L12: À faire
A13: T-304-I | B13: US-051 | C13: Secrétariat | D13: Exports | E13: Intégration API de la liste des étudiants par promotion avec regroupement par année d'entrée | F13: M. KOUASSI | G13: 46261 | H13: 46261 | I13: 3 | J13: =I13 -> 0 | K13: 3 | L13: À faire | M13: En attente de l'api
A14: T-306 | B14: US-040 | C14: Secrétariat | D14: Pré-inscription | E14: Écran liste des candidats ayant soumis leur pré-inscription en ligne | F14: M. KOUASSI | G14: 46262 | H14: 46262 | I14: 2 | J14: =I14 -> 0 | K14: 2 | L14: Terminée
A15: T-306-I | B15: US-040 | C15: Secrétariat | D15: Pré-inscription | E15: Intégration API de la liste des candidats ayant soumis leur pré-inscription en ligne | F15: M. KOUASSI | G15: 46262 | H15: 46262 | I15: 2 | J15: =I15 -> 0 | K15: 2 | L15: À faire | M15: En attente de l'api
A16: T-307 | B16: US-040 | C16: Secrétariat | D16: Pré-inscription | E16: Écran double liste (pré-inscription faite / non faite) par Église | F16: M. KOUASSI | G16: 46262 | H16: 46262 | I16: 2 | J16: =I16 -> 0 | K16: 2 | L16: À faire
A17: T-307-I | B17: US-040 | C17: Secrétariat | D17: Pré-inscription | E17: Intégration API de la double liste pré-inscription (faite / non faite) par Église | F17: M. KOUASSI | G17: 46262 | H17: 46262 | I17: 2 | J17: =I17 -> 0 | K17: 2 | L17: À faire | M17: En attente de l'api
A18: T-308 | B18: US-041 | C18: Secrétariat | D18: Pré-inscription | E18: Écran liste des dossiers dont les pièces sont à jour | F18: M. KOUASSI | G18: 46262 | H18: 46262 | I18: 2 | J18: =I18 -> 0 | K18: 2 | L18: À faire
A19: T-308-I | B19: US-041 | C19: Secrétariat | D19: Pré-inscription | E19: Intégration API de la liste des dossiers et contrôle de complétude des pièces | F19: M. KOUASSI | G19: 46262 | H19: 46262 | I19: 2 | J19: =I19 -> 0 | K19: 2 | L19: À faire | M19: En attente de l'api
A20: T-305 | B20: US-033 | C20: Église | D20: Suivi | E20: Écran vue consolidée des étudiants recommandés, regroupés par Église avec sous-totaux | F20: M. KOUASSI | G20: 46262 | H20: 46262 | I20: 2 | J20: =I20 -> 0 | K20: 2 | L20: À faire
A21: T-305-I | B21: US-033 | C21: Église | D21: Suivi | E21: Intégration API de la vue consolidée des étudiants recommandés, regroupés par Église avec sous-totaux | F21: M. KOUASSI | G21: 46262 | H21: 46262 | I21: 3 | J21: =I21 -> 0 | K21: 3 | L21: À faire | M21: En attente de l'api
A22: T-313 | B22: US-120 | C22: Secrétariat | D22: Campagne | E22: Écran liste des étudiants en stage (A3) avec statut du journal | F22: M. KOUASSI | G22: 46263 | H22: 46263 | I22: 1 | J22: =I22 -> 0 | K22: 1 | L22: À faire
A23: T-313-I | B23: US-120 | C23: Secrétariat | D23: Campagne | E23: Intégration API de la liste des étudiants en stage (A3) et lecture du statut du journal | F23: M. KOUASSI | G23: 46263 | H23: 46263 | I23: 2 | J23: =I23 -> 0 | K23: 2 | L23: À faire | M23: En attente de l'api
A24: T-314 | B24: US-131 | C24: Secrétariat | D24: Sessions | E24: Écran liste des étudiants en soutenance (A4) avec date de session prévue | F24: M. KOUASSI | G24: 46263 | H24: 46263 | I24: 1 | J24: =I24 -> 0 | K24: 1 | L24: À faire
A25: T-314-I | B25: US-131 | C25: Secrétariat | D25: Sessions | E25: Intégration API de la liste des étudiants en soutenance (A4) et récupération des dates de session | F25: M. KOUASSI | G25: 46263 | H25: 46263 | I25: 2 | J25: =I25 -> 0 | K25: 2 | L25: À faire | M25: En attente de l'api
A26: T-315 | B26: US-068 | C26: Direction | D26: Pilotage | E26: Tableau de bord Direction (niveau × promotion × Église) avec drill-down | F26: M. KOUASSI | G26: 46263 | H26: 46263 | I26: 3 | J26: =I26 -> 0 | K26: 3 | L26: À faire
A27: T-315-I | B27: US-068 | C27: Direction | D27: Pilotage | E27: Intégration API du tableau de bord Direction (agrégation niveau × promotion × Église) | F27: M. KOUASSI | G27: 46263 | H27: 46263 | I27: 3 | J27: =I27 -> 0 | K27: 3 | L27: À faire | M27: En attente de l'api
A28: T-316 | B28: US-067 | C28: Église | D28: Portail | E28: Vue de répartition par niveau sur la fiche Église | F28: M. KOUASSI | G28: 46263 | H28: 46263 | I28: 1 | J28: =I28 -> 0 | K28: 1 | L28: À faire
A29: T-316-I | B29: US-067 | C29: Église | D29: Portail | E29: Intégration API de la vue de répartition par niveau sur la fiche Église | F29: M. KOUASSI | G29: 46263 | H29: 46263 | I29: 2 | J29: =I29 -> 0 | K29: 2 | L29: À faire | M29: En attente de l'api
E30: TOTAL | I30: =SUM(I6:I29) -> 0 | J30: =SUM(J6:J29) -> 0

Sheet Sprint Backlog API du sprint 3
A1: Sprint Backlog — Sprint 3 API
A2: Du 07/09/2026 au 18/09/2026 · Décomposition en tâches techniques (8 h maximum par tâche), créée en Sprint Planning
A4: Sprint Goal | B4: Ce sprint, nous livrerons au Secrétariat académique et à la Direction les vues de consultation des dossiers étudiants (par niveau, promotion, année d'entrée, Église recommandatrice, statut de pré-inscription et complétude des pièces) ainsi que le contrôle et la validation de la recommandation d'un étudiant par son Église, afin que le Secrétariat puisse fiabiliser les inscriptions et ouvrir les accès portail en toute autonomie.
A6: ID tâche | B6: User Story | C6: Tâche technique | D6: Assigné à | E6: Date début | F6: Échéance | G6: Estimation (h) | H6: Reste à faire (h) | I6: Statut | J6: Observation
A7: API-301 | B7: US-043 | C7: Endpoint de validation de l'inscription définitive (contrôle de complétude, changement de statut, affectation promotion/niveau) | D7: ZRAN | E7: 46262 | F7: 46262 | G7: 1 | H7: 1 | I7: À faire
A8: API-302 | B8: US-044 | C8: Génération automatique du matricule EBAC-[ANNÉE]-[SÉQUENCE] sans collision de séquence | D8: ZRAN | E8: 46262 | F8: 46262 | G8: 1 | H8: 1 | I8: À faire
A9: API-303 | B9: US-072 | C9: Endpoint de liste des étudiants filtrée par niveau | D9: ZRAN | E9: 46263 | F9: 46263 | G9: 1 | H9: 1 | I9: À faire
A10: API-304 | B10: US-073 | C10: Endpoint de liste des étudiants filtrée par promotion et calcul des effectifs par statut | D10: ZRAN | E10: 46263 | F10: 46263 | G10: 1 | H10: 1 | I10: À faire
A11: API-305 | B11: US-074 | C11: Endpoint de liste consolidée des étudiants groupés par Église avec sous-totaux | D11: ZRAN | E11: 46263 | F11: 46263 | G11: 1 | H11: 1 | I11: À faire
A12: API-306 | B12: US-075 | C12: Endpoint de liste des candidats filtrée sur statut Pré-inscrit / Validé | D12: ZRAN | E12: 46263 | F12: 46263 | G12: 1 | H12: 1 | I12: À faire
A13: API-307 | B13: US-076 | C13: Endpoint de répartition des recommandés d'une Église par statut de pré-inscription | D13: ZRAN | E13: 46265 | F13: 46265 | G13: 1 | H13: 1 | I13: À faire
A14: API-308 | B14: US-077 | C14: Endpoint de calcul de la complétude des pièces par dossier | D14: ZRAN | E14: 46265 | F14: 46265 | G14: 1 | H14: 1 | I14: À faire
A15: API-309 | B15: US-078 | C15: Endpoint de croisement Église × complétude des pièces | D15: ZRAN | E15: 46265 | F15: 46265 | G15: 1 | H15: 1 | I15: À faire
A16: API-310 | B16: US-079 | C16: Endpoint de liste des pièces manquantes par dossier | D16: ZRAN | E16: 46265 | F16: 46265 | G16: 1 | H16: 1 | I16: À faire
A17: API-311 | B17: US-080 | C17: Endpoint de contrôle de l'Église recommandatrice avant validation | D17: ZRAN | E17: 46265 | F17: 46265 | G17: 1 | H17: 1 | I17: À faire
A18: API-312 | B18: US-081 | C18: Endpoint de validation de la recommandation et génération automatique du compte d'accès étudiant | D18: ZRAN | E18: 46266 | F18: 46266 | G18: 1 | H18: 1 | I18: À faire
... A22: API-316 | B22: US-085 | C22: Endpoint de répartition des recommandés d'une Église par niveau | D22: ZRAN | E22: 46266 | F22: 46266 | G22: 1 | H22: 1 | I22: À faire
C23: TOTAL | G23: =SUM(G7:G22) -> 0 | H23: =SUM(H7:H22) -> 0

Sheet US Enseignant Etudiant
A1: User stories — Enseignant et Étudiant
A2: 28 stories : 5 reprises et affinées, 23 nouvelles. Estimations proposées, sans déclaration de réalisation. Les captures décrivent le besoin, pas l’état de l’API.
A4: ID | B4: Epic | C4: Profil | D4: Fonctionnalité | E4: User Story | F4: Critères d’acceptation | G4: Priorité | H4: Points estimés | I4: Périmètre proposé | J4: Dépendances | K4: Sources | L4: Lien au Scrum 3 | M4: Statut
A5: US-086 | B5: EP-11 | C5: Enseignant | D5: Mes cours et détails matière | E5: En tant que enseignant, je veux consulter mes matières, modules et cours affectés par année et niveau, afin de préparer mes enseignements. | F5: Étant donné une affectation sur une matière entière ou certains cours, quand je consulte Mes cours, alors seuls les cours autorisés sont retournés, y compris par accès direct API. Quand je déplie une matière, alors le code, la promotion, le niveau, le volume horaire, les coefficients, les effectifs et les modules sont affichés sans doubler les étudiants inscrits à plusieurs cours. Quand aucune séance n’est planifiée, alors un état explicite est affiché ; les séances réalisées et planifiées sont distinguées. | G5: Must have | H5: 5 | I5: Sprint 4 — proposé | J5: Affectations pédagogiques et programme disponibles | K5: Images 1–3, 19 | L5: Nouvelle story | M5: Proposé — à valider en Planning
A6: US-087 | B6: EP-11 | C6: Enseignant | D6: Séances d’un cours | E6: En tant que enseignant, je veux consulter les séances datées d’un cours et leur état de présence, afin de identifier les appels restant à effectuer. | F6: Quand je sélectionne un cours affecté, alors ses séances affichent date, horaires, salle, contenu et statut de réalisation. Étant donné une séance réalisée sans feuille validée, quand je consulte son détail, alors Relever ouvre cette séance ; une feuille validée est consultable sans modification. | G6: Must have | H6: 3 | I6: Sprint 4 — proposé | J6: US-086 ; séances existantes | K6: Images 4 | L6: Nouvelle story | M6: Proposé — à valider en Planning
A7: US-088 | B7: EP-11 | C7: Enseignant | D7: Préparer la liste de présence | E7: En tant que enseignant, je veux marquer présents ou absents les étudiants inscrits à une séance, afin de fiabiliser l’appel avant validation. | F7: Quand je choisis matière, module, cours puis séance, alors chaque sélection filtre la suivante et la liste contient uniquement les inscrits de cette séance. Quand je change un statut avant validation, alors le compteur présents/inscrits et les absents sont actualisés sans clôturer la feuille. Quand un identifiant d’étudiant non inscrit ou une séance non affectée est envoyé, alors le serveur refuse la saisie. | G7: Must have | H7: 5 | I7: Sprint 4 — proposé | J7: US-087 ; inscriptions aux cours | K7: Images 5, 7 | L7: Nouvelle story | M7: Proposé — à valider en Planning
A8: US-061 | B8: EP-08 | C8: Enseignant | D8: Étudiants en rattrapage | E8: En tant que enseignant, je veux identifier les étudiants en rattrapage dans mes cours et listes de présence, afin de les prendre en compte avec la promotion titulaire. | F8: Étant donné un étudiant inscrit par le secrétariat à un rattrapage, quand je consulte le cours concerné, alors il apparaît une seule fois avec un indicateur Rattrapage et sa promotion d’origine. Quand je consulte un autre cours sans inscription de rattrapage, alors cet étudiant n’est pas ajouté à son effectif. | G8: Must have | H8: 3 | I8: Sprint 4 — proposé | J8: US-060 ; US-088 | K8: Images 1, 3, 5 | L8: Affinage de la story existante ; pas une nouvelle US | M8: Proposé — à valider en Planning
A9: US-089 | B9: EP-11 | C9: Enseignant | D9: Valider définitivement la présence | E9: En tant que enseignant, je veux confirmer définitivement une feuille de présence, afin de clôturer l’appel et déterminer l’éligibilité aux notes. | F9: Quand je demande la validation, alors une confirmation indique le nombre de présents et d’absents et les conséquences ; annuler conserve la feuille modifiable. Quand je confirme une feuille complète d’une séance réalisée, alors la validation est atomique et journalise l’auteur et la date ; toute modification ultérieure est refusée par le serveur. Quand un absent est confirmé, alors le cours est marqué à faire pour cet étudiant et la notation est bloquée ; une répétition de la requête ne crée pas de doublon. Quand tous sont présents, alors aucun cours à faire lié à cette absence n’est créé. Les règles multi-séances doivent être arbitrées avant développement. | G9: Must have | H9: 8 | I9: Sprint 4 — proposé | J9: US-088 ; décision D-01 | K9: Images 5–7 | L9: Nouvelle story | M9: Proposé — à valider en Planning
A10: US-090 | B10: EP-11 | C10: Enseignant | D10: Emploi du temps enseignant | E10: En tant que enseignant, je veux consulter mes créneaux hebdomadaires publiés, afin de organiser mes interventions. | F10: Étant donné une version publiée, quand je consulte mon emploi du temps, alors seuls mes créneaux affichent jour, horaires, cours, promotion, salle et version. Quand aucun planning n’est publié, alors un état indisponible est affiché ; les brouillons ne sont pas exposés. Quand je consulte un créneau récurrent, alors il reste distinct des séances datées du cahier de texte. | G10: Must have | H10: 3 | I10: Sprint 4 — proposé | J10: Planning publié et affectations | K10: Images 8 | L10: Nouvelle story | M10: Proposé — à valider en Planning
A11: US-091 | B11: EP-15 | C11: Enseignant | D11: Profil et affectations | E11: En tant que enseignant, je veux consulter mon identité professionnelle et mes affectations en vigueur, afin de vérifier mon dossier pédagogique. | F11: Quand j’ouvre mon profil, alors identité, matricule interne, fonction, ancienneté, contact et qualifications proviennent de mon dossier. Quand une affectation est affichée, alors matière entière ou cours précis est indiqué ; je ne peux modifier ni mon affectation ni celle d’un autre enseignant. | G11: Should have | H11: 2 | I11: Suite du backlog — non engagée | J11: Dossier personnel et affectations | K11: Images 19 | L11: Nouvelle story | M11: Proposé — à valider en Planning
A12: US-092 | B12: EP-11 | C12: Enseignant | D12: Cahier de texte | E12: En tant que enseignant, je veux consigner le contenu d’une séance dispensée, afin de tracer l’avancement pédagogique. | F12: Étant donné une séance affectée, quand je renseigne le contenu réalisé et l’enregistre, alors le journal conserve auteur et date et le cours affiche la réalisation. Quand les champs obligatoires sont absents ou la séance appartient à un autre enseignant, alors l’enregistrement est refusé. Le passage à Réalisée ne valide pas automatiquement la présence. Champs et possibilité de correction à confirmer faute de capture dédiée. | G12: Must have | H12: 5 | I12: Suite du backlog — non engagée | J12: Séances planifiées ; décision D-06 | K12: Images Menu image 2 ; image 4 | L12: Nouvelle story | M12: Proposé — à valider en Planning
A13: US-093 | B13: EP-10 | C13: Enseignant | D13: Saisir les notes éligibles | E13: En tant que enseignant, je veux saisir les notes sur 20 des étudiants autorisés après validation des présences, afin de évaluer les cours suivis. | F13: Étant donné une séance dispensée dont la feuille n’est pas validée, quand une note est envoyée, alors le serveur refuse et indique la présence à relever. Quand toutes les présences requises sont validées, alors seuls les étudiants éligibles peuvent recevoir une note ; un absent exclu ne reçoit ni note ni zéro automatique. Quand une note numérique entre 0 et 20 est enregistrée, alors elle reste provisoire ; les valeurs hors bornes sont rejetées et une feuille verrouillée est non modifiable. | G13: Must have | H13: 8 | I13: Suite du backlog — non engagée | J13: US-089 ; D-01 ; contrat de notes | K13: Images 9–10 | L13: Nouvelle story | M13: Proposé — à valider en Planning
A14: US-094 | B14: EP-10 | C14: Enseignant | D14: Moyenne provisoire de matière | E14: En tant que enseignant, je veux voir la moyenne recalculée après saisie des notes de cours, afin de contrôler le résultat avant transmission. | F14: Quand une note de cours éligible change, alors la moyenne de matière est recalculée selon les coefficients de cours applicables et reste provisoire. Quand des cours restent à faire, alors ils ne deviennent pas des zéros ; la moyenne est signalée partielle et ne valide pas automatiquement la matière. Quand aucune note éligible n’existe, alors aucune division par zéro n’est effectuée ; pondération et arrondis sont confirmés par D-02. | G14: Must have | H14: 5 | I14: Suite du backlog — non engagée | J14: US-093 ; D-02 | K14: Images 9–10 | L14: Nouvelle story | M14: Proposé — à valider en Planning
A15: US-095 | B15: EP-10 | C15: Enseignant | D15: Transmettre et suivre la feuille de notes | E15: En tant que enseignant, je veux transmettre une feuille complète au secrétariat et suivre sa validation, afin de obtenir une publication officielle. | F15: Quand un étudiant éligible n’a pas de note ou qu’un appel requis manque, alors la transmission est refusée côté serveur. Quand je transmets une feuille complète, alors elle passe au contrôle du secrétariat et je vois ensuite la transmission à la Direction puis la validation et le verrouillage. Quand un enseignant tente de valider au nom de la Direction, alors l’action est refusée ; le circuit de retour pour correction doit être défini. | G15: Must have | H15: 5 | I15: Suite du backlog — non engagée | J15: US-093–094 ; workflow Secrétariat/Direction | K15: Images 9–10 | L15: Nouvelle story | M15: Proposé — à valider en Planning
A16: US-096 | B16: EP-10 | C16: Enseignant | D16: Demander une correction de note | E16: En tant que enseignant, je veux proposer une correction motivée d’une note publiée, afin de faire rectifier une erreur sans modifier directement une note verrouillée. | F16: Quand je sélectionne une note publiée de mon cours, alors la valeur actuelle est affichée et la note proposée entre 0 et 20 ainsi que le motif sont obligatoires. Quand je transmets, alors une demande En attente autorisation est créée ; la note officielle reste inchangée avant autorisation et application. Quand je tente de corriger la note d’un cours non affecté, alors le serveur refuse. | G16: Must have | H16: 5 | I16: Suite du backlog — non engagée | J16: Notes publiées ; workflow Direction/Secrétariat | K16: Images 11–12, 14 | L16: Nouvelle story | M16: Proposé — à valider en Planning
... A32: US-108 | B32: EP-11 | C32: Étudiant | D32: Supports de cours | E32: En tant que étudiant, je veux consulter et télécharger les supports et leurs versions autorisées, afin de étudier les contenus mis à disposition par mes enseignants. | F32: Quand je consulte les supports, alors ils sont classés par matière, module et cours avec enseignant, type, format, taille, date et version ; je peux rechercher une matière. Quand un cours est ouvert selon mon inscription et mes droits, alors ses documents et versions sont téléchargeables ; un cours futur ou manqué non réinscrit reste fermé selon D-03. Quand je tente un téléchargement direct hors de mes droits ou une publication de version, alors le serveur refuse ; je ne peux pas republier comme un enseignant. | G32: Must have | H32: 5 | I32: Suite du backlog — non engagée | J32: US-099–101 ; US-064 ; D-03 | K32: Images 29–30 | L32: Nouvelle story | M32: Proposé — à valider en Planning

Sheet Cadrage Sprint 4
A1: Sprint 4 — proposition de planification
A2: Document de travail fondé sur Scrum 3 et les 30 captures du 08/09/2026. Le classeur source reste inchangé.
A4: Sujet | B4: Proposition | C4: Conditions / limites
A5: Objectif | B5: Permettre aux enseignants de consulter leurs cours et plannings, de relever et valider les présences, et aux étudiants de consulter leurs matières, cours à faire, progression et planning dans un espace cloisonné. | C5: Livrer un parcours démontrable : cours → appel → cours à faire → consultation étudiant.
A6: Dates | B6: 21/09/2026 au 02/10/2026 — 10 jours ouvrés | C6: Hypothèse dans la continuité du Sprint 3 annoncé du 07/09 au 18/09 ; les dates de tâches du Scrum 3 sont incohérentes et ne sont pas reprises.
A7: Périmètre | B7: 11 stories / 42 points proposés | C7: Les autres stories sont définies dans le backlog mais ne sont pas engagées dans ce sprint.
A8: Charge Frontend | B8: 47 h : 43 h de stories + 4 h intégration/recette | C8: M. KOUASSI proposé d’après Scrum 3 ; disponibilité à confirmer.
A9: Charge API | B9: 60 h : 56 h de stories + 4 h intégration/recette | C9: ZRAN proposé d’après Scrum 3 ; disponibilité à confirmer.
A10: Capacité | B10: Hypothèse : 2 intervenants × 10 jours × 6 h utiles = 120 h | C10: Budget cible : 60 h par intervenant. API : aucune marge dans cette hypothèse ; retirer ou réduire une story si la disponibilité baisse. Les story points ne sont pas des heures.
A11: Prérequis | B11: Authentification, programme, affectations, inscriptions aux cours et planning publié accessibles via API | C11: Le cahier de texte et la création du planning ne sont pas développés dans ce lot : séances et planning doivent déjà être fournis. Replanifier sinon.
A12: Condition bloquante | B12: Arbitrer D-01 avant de développer US-089 | C12: La règle « une absence rend tout le cours à faire » doit être précisée pour les cours comportant plusieurs séances.
A13: Suite prioritaire | B13: Notes et validation ; bibliothèque et supports ; bulletins ; inscription/paiement et finances | C13: Ordre proposé. Un périmètre complet de toutes les captures nécessite plusieurs sprints ou une capacité accrue.
A14: Menus non détaillés | B14: Tableau de bord enseignant, journal de stage, ma soutenance, notifications et réglages de profil | C14: Visibles uniquement dans les menus ; aucune fonctionnalité détaillée ni engagement de livraison n’est inventé. Le cahier de texte a une story provisoire US-092.
A15: Définition de prêt | B15: Règles arbitrées, sources identifiées, contrats API convenus, données de recette disponibles et estimation revue | C15: Aucune story ne devient prête automatiquement par la présence d’une capture.
... A19: Conservation du Scrum 3 | B19: Toutes les feuilles originales sont conservées comme référence historique | C19: Le plan Sprint 4 et les affinages font foi uniquement après validation du Planning ; aucun déploiement applicatif n’est réalisé.

Sheet Selection Sprint 4
A1: Sprint 4 — stories sélectionnées
A2: Permettre aux enseignants de consulter leurs cours et plannings, de relever et valider les présences, et aux étudiants de consulter leurs matières, cours à faire, progression et planning dans un espace cloisonné.
A4: US | B4: Profil | C4: Livrable | D4: Points estimés | E4: Frontend (h) | F4: API (h) | G4: Dépendances | H4: Statut
A5: US-086 | B5: Enseignant | C5: Mes cours et détails matière | D5: 5 | E5: 6 | F5: 8 | G5: Affectations pédagogiques et programme disponibles | H5: À faire
A6: US-087 | B6: Enseignant | C6: Séances d’un cours | D6: 3 | E6: 4 | F6: 4 | G6: US-086 ; séances existantes | H6: À faire
A7: US-088 | B7: Enseignant | C7: Préparer la liste de présence | D7: 5 | E7: 6 | F7: 8 | G7: US-087 ; inscriptions aux cours | H7: À faire
A8: US-061 | B8: Enseignant | C8: Étudiants en rattrapage | D8: 3 | E8: 2 | F8: 4 | G8: US-060 ; US-088 | H8: À faire
A9: US-089 | B9: Enseignant | C9: Valider définitivement la présence | D9: 8 | E9: 4 | F9: 8 | G9: US-088 ; décision D-01 | H9: À faire
A10: US-090 | B10: Enseignant | C10: Emploi du temps enseignant | D10: 3 | E10: 4 | F10: 4 | G10: Planning publié et affectations | H10: À faire
A11: US-064 | B11: Étudiant | C11: Accès personnel au portail | D11: 3 | E11: 4 | F11: 4 | G11: Authentification existante ; compte lié au dossier | H11: À faire
A12: US-065 | B12: Étudiant | C12: Mes matières | D12: 3 | E12: 4 | F12: 4 | G12: US-064 ; résultats et programme | H12: À faire
A13: US-066 | B13: Étudiant | C13: Mes cours à faire | D13: 3 | E13: 3 | F13: 4 | G13: US-064 ; US-060 ; US-089 | H13: À faire
A14: US-058 | B14: Étudiant | C14: Ma progression | D14: 3 | E14: 3 | F14: 4 | G14: US-065 ; validations officielles | H14: À faire
A15: US-103 | B15: Étudiant | C15: Emploi du temps étudiant | D15: 3 | E15: 3 | F15: 4 | G15: US-064 ; planning publié ; US-060 | H15: À faire

Sheet Sprint 4 Frontend
A1: Sprint Backlog — Sprint 4 Frontend
A2: Dates, responsables et charges prévisionnels. Tâches ≤ 8 h ; séquencement à revoir en Planning. Frontend : contrat et mocks partagés avant intégration réelle.
